Traceback (most recent call last):
  File "rasterio/_base.pyx", line 310, in rasterio._base.DatasetBase.__init__
  File "rasterio/_base.pyx", line 221, in rasterio._base.open_dataset
  File "rasterio/_err.pyx", line 221, in rasterio._err.exc_wrap_pointer
rasterio._err.CPLE_OpenFailedError: './temp_daily_maps/mean/2024_02_06_mean.tif' not recognized as a supported file format.

During handling of the above exception, another exception occurred:

Traceback (most recent call last):
  File "/var/www/html/Python/temp_daily.py", line 60, in <module>
    with rasterio.open(f'./temp_daily_maps/{n}/{yest_year}_{yest_mon:02d}_{yest_day:02d}_{n}.tif') as src:
  File "/home/cherryle/.local/lib/python3.10/site-packages/rasterio/env.py", line 451, in wrapper
    return f(*args, **kwds)
  File "/home/cherryle/.local/lib/python3.10/site-packages/rasterio/__init__.py", line 304, in open
    dataset = DatasetReader(path, driver=driver, sharing=sharing, **kwargs)
  File "rasterio/_base.pyx", line 312, in rasterio._base.DatasetBase.__init__
rasterio.errors.RasterioIOError: './temp_daily_maps/mean/2024_02_06_mean.tif' not recognized as a supported file format.
Traceback (most recent call last):
  File "rasterio/_base.pyx", line 310, in rasterio._base.DatasetBase.__init__
  File "rasterio/_base.pyx", line 221, in rasterio._base.open_dataset
  File "rasterio/_err.pyx", line 221, in rasterio._err.exc_wrap_pointer
rasterio._err.CPLE_OpenFailedError: './temp_daily_maps/mean/2024_02_07_mean.tif' not recognized as a supported file format.

During handling of the above exception, another exception occurred:

Traceback (most recent call last):
  File "/var/www/html/Python/temp_daily.py", line 60, in <module>
    with rasterio.open(f'./temp_daily_maps/{n}/{yest_year}_{yest_mon:02d}_{yest_day:02d}_{n}.tif') as src:
  File "/home/cherryle/.local/lib/python3.10/site-packages/rasterio/env.py", line 451, in wrapper
    return f(*args, **kwds)
  File "/home/cherryle/.local/lib/python3.10/site-packages/rasterio/__init__.py", line 304, in open
    dataset = DatasetReader(path, driver=driver, sharing=sharing, **kwargs)
  File "rasterio/_base.pyx", line 312, in rasterio._base.DatasetBase.__init__
rasterio.errors.RasterioIOError: './temp_daily_maps/mean/2024_02_07_mean.tif' not recognized as a supported file format.
Traceback (most recent call last):
  File "rasterio/_base.pyx", line 310, in rasterio._base.DatasetBase.__init__
  File "rasterio/_base.pyx", line 221, in rasterio._base.open_dataset
  File "rasterio/_err.pyx", line 221, in rasterio._err.exc_wrap_pointer
rasterio._err.CPLE_OpenFailedError: './temp_daily_maps/mean/2024_02_08_mean.tif' not recognized as a supported file format.

During handling of the above exception, another exception occurred:

Traceback (most recent call last):
  File "/var/www/html/Python/temp_daily.py", line 60, in <module>
    with rasterio.open(f'./temp_daily_maps/{n}/{yest_year}_{yest_mon:02d}_{yest_day:02d}_{n}.tif') as src:
  File "/home/cherryle/.local/lib/python3.10/site-packages/rasterio/env.py", line 451, in wrapper
    return f(*args, **kwds)
  File "/home/cherryle/.local/lib/python3.10/site-packages/rasterio/__init__.py", line 304, in open
    dataset = DatasetReader(path, driver=driver, sharing=sharing, **kwargs)
  File "rasterio/_base.pyx", line 312, in rasterio._base.DatasetBase.__init__
rasterio.errors.RasterioIOError: './temp_daily_maps/mean/2024_02_08_mean.tif' not recognized as a supported file format.
Traceback (most recent call last):
  File "rasterio/_base.pyx", line 310, in rasterio._base.DatasetBase.__init__
  File "rasterio/_base.pyx", line 221, in rasterio._base.open_dataset
  File "rasterio/_err.pyx", line 221, in rasterio._err.exc_wrap_pointer
rasterio._err.CPLE_OpenFailedError: './temp_daily_maps/mean/2024_02_15_mean.tif' not recognized as a supported file format.

During handling of the above exception, another exception occurred:

Traceback (most recent call last):
  File "/var/www/html/Python/temp_daily.py", line 60, in <module>
    with rasterio.open(f'./temp_daily_maps/{n}/{yest_year}_{yest_mon:02d}_{yest_day:02d}_{n}.tif') as src:
  File "/home/cherryle/.local/lib/python3.10/site-packages/rasterio/env.py", line 451, in wrapper
    return f(*args, **kwds)
  File "/home/cherryle/.local/lib/python3.10/site-packages/rasterio/__init__.py", line 304, in open
    dataset = DatasetReader(path, driver=driver, sharing=sharing, **kwargs)
  File "rasterio/_base.pyx", line 312, in rasterio._base.DatasetBase.__init__
rasterio.errors.RasterioIOError: './temp_daily_maps/mean/2024_02_15_mean.tif' not recognized as a supported file format.
Traceback (most recent call last):
  File "rasterio/_base.pyx", line 310, in rasterio._base.DatasetBase.__init__
  File "rasterio/_base.pyx", line 221, in rasterio._base.open_dataset
  File "rasterio/_err.pyx", line 221, in rasterio._err.exc_wrap_pointer
rasterio._err.CPLE_OpenFailedError: './temp_daily_maps/mean/2024_02_20_mean.tif' not recognized as a supported file format.

During handling of the above exception, another exception occurred:

Traceback (most recent call last):
  File "/var/www/html/Python/temp_daily.py", line 60, in <module>
    with rasterio.open(f'./temp_daily_maps/{n}/{yest_year}_{yest_mon:02d}_{yest_day:02d}_{n}.tif') as src:
  File "/home/cherryle/.local/lib/python3.10/site-packages/rasterio/env.py", line 451, in wrapper
    return f(*args, **kwds)
  File "/home/cherryle/.local/lib/python3.10/site-packages/rasterio/__init__.py", line 304, in open
    dataset = DatasetReader(path, driver=driver, sharing=sharing, **kwargs)
  File "rasterio/_base.pyx", line 312, in rasterio._base.DatasetBase.__init__
rasterio.errors.RasterioIOError: './temp_daily_maps/mean/2024_02_20_mean.tif' not recognized as a supported file format.
Traceback (most recent call last):
  File "rasterio/_base.pyx", line 310, in rasterio._base.DatasetBase.__init__
  File "rasterio/_base.pyx", line 221, in rasterio._base.open_dataset
  File "rasterio/_err.pyx", line 221, in rasterio._err.exc_wrap_pointer
rasterio._err.CPLE_OpenFailedError: './temp_daily_maps/mean/2024_02_26_mean.tif' not recognized as a supported file format.

During handling of the above exception, another exception occurred:

Traceback (most recent call last):
  File "/var/www/html/Python/temp_daily.py", line 60, in <module>
    with rasterio.open(f'./temp_daily_maps/{n}/{yest_year}_{yest_mon:02d}_{yest_day:02d}_{n}.tif') as src:
  File "/home/cherryle/.local/lib/python3.10/site-packages/rasterio/env.py", line 451, in wrapper
    return f(*args, **kwds)
  File "/home/cherryle/.local/lib/python3.10/site-packages/rasterio/__init__.py", line 304, in open
    dataset = DatasetReader(path, driver=driver, sharing=sharing, **kwargs)
  File "rasterio/_base.pyx", line 312, in rasterio._base.DatasetBase.__init__
rasterio.errors.RasterioIOError: './temp_daily_maps/mean/2024_02_26_mean.tif' not recognized as a supported file format.
Traceback (most recent call last):
  File "rasterio/_base.pyx", line 310, in rasterio._base.DatasetBase.__init__
  File "rasterio/_base.pyx", line 221, in rasterio._base.open_dataset
  File "rasterio/_err.pyx", line 221, in rasterio._err.exc_wrap_pointer
rasterio._err.CPLE_OpenFailedError: './temp_daily_maps/mean/2024_02_27_mean.tif' not recognized as a supported file format.

During handling of the above exception, another exception occurred:

Traceback (most recent call last):
  File "/var/www/html/Python/temp_daily.py", line 60, in <module>
    with rasterio.open(f'./temp_daily_maps/{n}/{yest_year}_{yest_mon:02d}_{yest_day:02d}_{n}.tif') as src:
  File "/home/cherryle/.local/lib/python3.10/site-packages/rasterio/env.py", line 451, in wrapper
    return f(*args, **kwds)
  File "/home/cherryle/.local/lib/python3.10/site-packages/rasterio/__init__.py", line 304, in open
    dataset = DatasetReader(path, driver=driver, sharing=sharing, **kwargs)
  File "rasterio/_base.pyx", line 312, in rasterio._base.DatasetBase.__init__
rasterio.errors.RasterioIOError: './temp_daily_maps/mean/2024_02_27_mean.tif' not recognized as a supported file format.
