Traceback (most recent call last):
  File "rasterio/_base.pyx", line 310, in rasterio._base.DatasetBase.__init__
  File "rasterio/_base.pyx", line 221, in rasterio._base.open_dataset
  File "rasterio/_err.pyx", line 221, in rasterio._err.exc_wrap_pointer
rasterio._err.CPLE_OpenFailedError: './temp_daily_maps/mean/2024_06_24_mean.tif' not recognized as a supported file format.

During handling of the above exception, another exception occurred:

Traceback (most recent call last):
  File "/var/www/html/Python/temp_daily.py", line 60, in <module>
    with rasterio.open(f'./temp_daily_maps/{n}/{yest_year}_{yest_mon:02d}_{yest_day:02d}_{n}.tif') as src:
  File "/home/cherryle/.local/lib/python3.10/site-packages/rasterio/env.py", line 451, in wrapper
    return f(*args, **kwds)
  File "/home/cherryle/.local/lib/python3.10/site-packages/rasterio/__init__.py", line 304, in open
    dataset = DatasetReader(path, driver=driver, sharing=sharing, **kwargs)
  File "rasterio/_base.pyx", line 312, in rasterio._base.DatasetBase.__init__
rasterio.errors.RasterioIOError: './temp_daily_maps/mean/2024_06_24_mean.tif' not recognized as a supported file format.
Traceback (most recent call last):
  File "rasterio/_base.pyx", line 310, in rasterio._base.DatasetBase.__init__
  File "rasterio/_base.pyx", line 221, in rasterio._base.open_dataset
  File "rasterio/_err.pyx", line 221, in rasterio._err.exc_wrap_pointer
rasterio._err.CPLE_OpenFailedError: './temp_daily_maps/mean/2024_06_25_mean.tif' not recognized as a supported file format.

During handling of the above exception, another exception occurred:

Traceback (most recent call last):
  File "/var/www/html/Python/temp_daily.py", line 60, in <module>
    with rasterio.open(f'./temp_daily_maps/{n}/{yest_year}_{yest_mon:02d}_{yest_day:02d}_{n}.tif') as src:
  File "/home/cherryle/.local/lib/python3.10/site-packages/rasterio/env.py", line 451, in wrapper
    return f(*args, **kwds)
  File "/home/cherryle/.local/lib/python3.10/site-packages/rasterio/__init__.py", line 304, in open
    dataset = DatasetReader(path, driver=driver, sharing=sharing, **kwargs)
  File "rasterio/_base.pyx", line 312, in rasterio._base.DatasetBase.__init__
rasterio.errors.RasterioIOError: './temp_daily_maps/mean/2024_06_25_mean.tif' not recognized as a supported file format.
Traceback (most recent call last):
  File "rasterio/_base.pyx", line 310, in rasterio._base.DatasetBase.__init__
  File "rasterio/_base.pyx", line 221, in rasterio._base.open_dataset
  File "rasterio/_err.pyx", line 221, in rasterio._err.exc_wrap_pointer
rasterio._err.CPLE_OpenFailedError: './temp_daily_maps/mean/2024_07_02_mean.tif' not recognized as a supported file format.

During handling of the above exception, another exception occurred:

Traceback (most recent call last):
  File "/var/www/html/Python/temp_daily.py", line 60, in <module>
    with rasterio.open(f'./temp_daily_maps/{n}/{yest_year}_{yest_mon:02d}_{yest_day:02d}_{n}.tif') as src:
  File "/home/cherryle/.local/lib/python3.10/site-packages/rasterio/env.py", line 451, in wrapper
    return f(*args, **kwds)
  File "/home/cherryle/.local/lib/python3.10/site-packages/rasterio/__init__.py", line 304, in open
    dataset = DatasetReader(path, driver=driver, sharing=sharing, **kwargs)
  File "rasterio/_base.pyx", line 312, in rasterio._base.DatasetBase.__init__
rasterio.errors.RasterioIOError: './temp_daily_maps/mean/2024_07_02_mean.tif' not recognized as a supported file format.
Traceback (most recent call last):
  File "rasterio/_base.pyx", line 310, in rasterio._base.DatasetBase.__init__
  File "rasterio/_base.pyx", line 221, in rasterio._base.open_dataset
  File "rasterio/_err.pyx", line 221, in rasterio._err.exc_wrap_pointer
rasterio._err.CPLE_OpenFailedError: './temp_daily_maps/mean/2024_07_03_mean.tif' not recognized as a supported file format.

During handling of the above exception, another exception occurred:

Traceback (most recent call last):
  File "/var/www/html/Python/temp_daily.py", line 60, in <module>
    with rasterio.open(f'./temp_daily_maps/{n}/{yest_year}_{yest_mon:02d}_{yest_day:02d}_{n}.tif') as src:
  File "/home/cherryle/.local/lib/python3.10/site-packages/rasterio/env.py", line 451, in wrapper
    return f(*args, **kwds)
  File "/home/cherryle/.local/lib/python3.10/site-packages/rasterio/__init__.py", line 304, in open
    dataset = DatasetReader(path, driver=driver, sharing=sharing, **kwargs)
  File "rasterio/_base.pyx", line 312, in rasterio._base.DatasetBase.__init__
rasterio.errors.RasterioIOError: './temp_daily_maps/mean/2024_07_03_mean.tif' not recognized as a supported file format.
Traceback (most recent call last):
  File "rasterio/_base.pyx", line 310, in rasterio._base.DatasetBase.__init__
  File "rasterio/_base.pyx", line 221, in rasterio._base.open_dataset
  File "rasterio/_err.pyx", line 221, in rasterio._err.exc_wrap_pointer
rasterio._err.CPLE_OpenFailedError: './temp_daily_maps/mean/2024_07_04_mean.tif' not recognized as a supported file format.

During handling of the above exception, another exception occurred:

Traceback (most recent call last):
  File "/var/www/html/Python/temp_daily.py", line 60, in <module>
    with rasterio.open(f'./temp_daily_maps/{n}/{yest_year}_{yest_mon:02d}_{yest_day:02d}_{n}.tif') as src:
  File "/home/cherryle/.local/lib/python3.10/site-packages/rasterio/env.py", line 451, in wrapper
    return f(*args, **kwds)
  File "/home/cherryle/.local/lib/python3.10/site-packages/rasterio/__init__.py", line 304, in open
    dataset = DatasetReader(path, driver=driver, sharing=sharing, **kwargs)
  File "rasterio/_base.pyx", line 312, in rasterio._base.DatasetBase.__init__
rasterio.errors.RasterioIOError: './temp_daily_maps/mean/2024_07_04_mean.tif' not recognized as a supported file format.
Traceback (most recent call last):
  File "rasterio/_base.pyx", line 310, in rasterio._base.DatasetBase.__init__
  File "rasterio/_base.pyx", line 221, in rasterio._base.open_dataset
  File "rasterio/_err.pyx", line 221, in rasterio._err.exc_wrap_pointer
rasterio._err.CPLE_OpenFailedError: './temp_daily_maps/mean/2024_07_05_mean.tif' not recognized as a supported file format.

During handling of the above exception, another exception occurred:

Traceback (most recent call last):
  File "/var/www/html/Python/temp_daily.py", line 60, in <module>
    with rasterio.open(f'./temp_daily_maps/{n}/{yest_year}_{yest_mon:02d}_{yest_day:02d}_{n}.tif') as src:
  File "/home/cherryle/.local/lib/python3.10/site-packages/rasterio/env.py", line 451, in wrapper
    return f(*args, **kwds)
  File "/home/cherryle/.local/lib/python3.10/site-packages/rasterio/__init__.py", line 304, in open
    dataset = DatasetReader(path, driver=driver, sharing=sharing, **kwargs)
  File "rasterio/_base.pyx", line 312, in rasterio._base.DatasetBase.__init__
rasterio.errors.RasterioIOError: './temp_daily_maps/mean/2024_07_05_mean.tif' not recognized as a supported file format.
Traceback (most recent call last):
  File "rasterio/_base.pyx", line 310, in rasterio._base.DatasetBase.__init__
  File "rasterio/_base.pyx", line 221, in rasterio._base.open_dataset
  File "rasterio/_err.pyx", line 221, in rasterio._err.exc_wrap_pointer
rasterio._err.CPLE_OpenFailedError: './temp_daily_maps/mean/2024_07_06_mean.tif' not recognized as a supported file format.

During handling of the above exception, another exception occurred:

Traceback (most recent call last):
  File "/var/www/html/Python/temp_daily.py", line 60, in <module>
    with rasterio.open(f'./temp_daily_maps/{n}/{yest_year}_{yest_mon:02d}_{yest_day:02d}_{n}.tif') as src:
  File "/home/cherryle/.local/lib/python3.10/site-packages/rasterio/env.py", line 451, in wrapper
    return f(*args, **kwds)
  File "/home/cherryle/.local/lib/python3.10/site-packages/rasterio/__init__.py", line 304, in open
    dataset = DatasetReader(path, driver=driver, sharing=sharing, **kwargs)
  File "rasterio/_base.pyx", line 312, in rasterio._base.DatasetBase.__init__
rasterio.errors.RasterioIOError: './temp_daily_maps/mean/2024_07_06_mean.tif' not recognized as a supported file format.
Traceback (most recent call last):
  File "rasterio/_base.pyx", line 310, in rasterio._base.DatasetBase.__init__
  File "rasterio/_base.pyx", line 221, in rasterio._base.open_dataset
  File "rasterio/_err.pyx", line 221, in rasterio._err.exc_wrap_pointer
rasterio._err.CPLE_OpenFailedError: './temp_daily_maps/mean/2024_07_07_mean.tif' not recognized as a supported file format.

During handling of the above exception, another exception occurred:

Traceback (most recent call last):
  File "/var/www/html/Python/temp_daily.py", line 60, in <module>
    with rasterio.open(f'./temp_daily_maps/{n}/{yest_year}_{yest_mon:02d}_{yest_day:02d}_{n}.tif') as src:
  File "/home/cherryle/.local/lib/python3.10/site-packages/rasterio/env.py", line 451, in wrapper
    return f(*args, **kwds)
  File "/home/cherryle/.local/lib/python3.10/site-packages/rasterio/__init__.py", line 304, in open
    dataset = DatasetReader(path, driver=driver, sharing=sharing, **kwargs)
  File "rasterio/_base.pyx", line 312, in rasterio._base.DatasetBase.__init__
rasterio.errors.RasterioIOError: './temp_daily_maps/mean/2024_07_07_mean.tif' not recognized as a supported file format.
Traceback (most recent call last):
  File "rasterio/_base.pyx", line 310, in rasterio._base.DatasetBase.__init__
  File "rasterio/_base.pyx", line 221, in rasterio._base.open_dataset
  File "rasterio/_err.pyx", line 221, in rasterio._err.exc_wrap_pointer
rasterio._err.CPLE_OpenFailedError: './temp_daily_maps/mean/2024_07_08_mean.tif' not recognized as a supported file format.

During handling of the above exception, another exception occurred:

Traceback (most recent call last):
  File "/var/www/html/Python/temp_daily.py", line 60, in <module>
    with rasterio.open(f'./temp_daily_maps/{n}/{yest_year}_{yest_mon:02d}_{yest_day:02d}_{n}.tif') as src:
  File "/home/cherryle/.local/lib/python3.10/site-packages/rasterio/env.py", line 451, in wrapper
    return f(*args, **kwds)
  File "/home/cherryle/.local/lib/python3.10/site-packages/rasterio/__init__.py", line 304, in open
    dataset = DatasetReader(path, driver=driver, sharing=sharing, **kwargs)
  File "rasterio/_base.pyx", line 312, in rasterio._base.DatasetBase.__init__
rasterio.errors.RasterioIOError: './temp_daily_maps/mean/2024_07_08_mean.tif' not recognized as a supported file format.
Traceback (most recent call last):
  File "rasterio/_base.pyx", line 310, in rasterio._base.DatasetBase.__init__
  File "rasterio/_base.pyx", line 221, in rasterio._base.open_dataset
  File "rasterio/_err.pyx", line 221, in rasterio._err.exc_wrap_pointer
rasterio._err.CPLE_OpenFailedError: './temp_daily_maps/mean/2024_07_09_mean.tif' not recognized as a supported file format.

During handling of the above exception, another exception occurred:

Traceback (most recent call last):
  File "/var/www/html/Python/temp_daily.py", line 60, in <module>
    with rasterio.open(f'./temp_daily_maps/{n}/{yest_year}_{yest_mon:02d}_{yest_day:02d}_{n}.tif') as src:
  File "/home/cherryle/.local/lib/python3.10/site-packages/rasterio/env.py", line 451, in wrapper
    return f(*args, **kwds)
  File "/home/cherryle/.local/lib/python3.10/site-packages/rasterio/__init__.py", line 304, in open
    dataset = DatasetReader(path, driver=driver, sharing=sharing, **kwargs)
  File "rasterio/_base.pyx", line 312, in rasterio._base.DatasetBase.__init__
rasterio.errors.RasterioIOError: './temp_daily_maps/mean/2024_07_09_mean.tif' not recognized as a supported file format.
Traceback (most recent call last):
  File "rasterio/_base.pyx", line 310, in rasterio._base.DatasetBase.__init__
  File "rasterio/_base.pyx", line 221, in rasterio._base.open_dataset
  File "rasterio/_err.pyx", line 221, in rasterio._err.exc_wrap_pointer
rasterio._err.CPLE_OpenFailedError: './temp_daily_maps/mean/2024_07_10_mean.tif' not recognized as a supported file format.

During handling of the above exception, another exception occurred:

Traceback (most recent call last):
  File "/var/www/html/Python/temp_daily.py", line 60, in <module>
    with rasterio.open(f'./temp_daily_maps/{n}/{yest_year}_{yest_mon:02d}_{yest_day:02d}_{n}.tif') as src:
  File "/home/cherryle/.local/lib/python3.10/site-packages/rasterio/env.py", line 451, in wrapper
    return f(*args, **kwds)
  File "/home/cherryle/.local/lib/python3.10/site-packages/rasterio/__init__.py", line 304, in open
    dataset = DatasetReader(path, driver=driver, sharing=sharing, **kwargs)
  File "rasterio/_base.pyx", line 312, in rasterio._base.DatasetBase.__init__
rasterio.errors.RasterioIOError: './temp_daily_maps/mean/2024_07_10_mean.tif' not recognized as a supported file format.
Traceback (most recent call last):
  File "rasterio/_base.pyx", line 310, in rasterio._base.DatasetBase.__init__
  File "rasterio/_base.pyx", line 221, in rasterio._base.open_dataset
  File "rasterio/_err.pyx", line 221, in rasterio._err.exc_wrap_pointer
rasterio._err.CPLE_OpenFailedError: './temp_daily_maps/mean/2024_07_11_mean.tif' not recognized as a supported file format.

During handling of the above exception, another exception occurred:

Traceback (most recent call last):
  File "/var/www/html/Python/temp_daily.py", line 60, in <module>
    with rasterio.open(f'./temp_daily_maps/{n}/{yest_year}_{yest_mon:02d}_{yest_day:02d}_{n}.tif') as src:
  File "/home/cherryle/.local/lib/python3.10/site-packages/rasterio/env.py", line 451, in wrapper
    return f(*args, **kwds)
  File "/home/cherryle/.local/lib/python3.10/site-packages/rasterio/__init__.py", line 304, in open
    dataset = DatasetReader(path, driver=driver, sharing=sharing, **kwargs)
  File "rasterio/_base.pyx", line 312, in rasterio._base.DatasetBase.__init__
rasterio.errors.RasterioIOError: './temp_daily_maps/mean/2024_07_11_mean.tif' not recognized as a supported file format.
Traceback (most recent call last):
  File "rasterio/_base.pyx", line 310, in rasterio._base.DatasetBase.__init__
  File "rasterio/_base.pyx", line 221, in rasterio._base.open_dataset
  File "rasterio/_err.pyx", line 221, in rasterio._err.exc_wrap_pointer
rasterio._err.CPLE_OpenFailedError: './temp_daily_maps/mean/2024_07_12_mean.tif' not recognized as a supported file format.

During handling of the above exception, another exception occurred:

Traceback (most recent call last):
  File "/var/www/html/Python/temp_daily.py", line 60, in <module>
    with rasterio.open(f'./temp_daily_maps/{n}/{yest_year}_{yest_mon:02d}_{yest_day:02d}_{n}.tif') as src:
  File "/home/cherryle/.local/lib/python3.10/site-packages/rasterio/env.py", line 451, in wrapper
    return f(*args, **kwds)
  File "/home/cherryle/.local/lib/python3.10/site-packages/rasterio/__init__.py", line 304, in open
    dataset = DatasetReader(path, driver=driver, sharing=sharing, **kwargs)
  File "rasterio/_base.pyx", line 312, in rasterio._base.DatasetBase.__init__
rasterio.errors.RasterioIOError: './temp_daily_maps/mean/2024_07_12_mean.tif' not recognized as a supported file format.
Traceback (most recent call last):
  File "rasterio/_base.pyx", line 310, in rasterio._base.DatasetBase.__init__
  File "rasterio/_base.pyx", line 221, in rasterio._base.open_dataset
  File "rasterio/_err.pyx", line 221, in rasterio._err.exc_wrap_pointer
rasterio._err.CPLE_OpenFailedError: './temp_daily_maps/mean/2024_07_13_mean.tif' not recognized as a supported file format.

During handling of the above exception, another exception occurred:

Traceback (most recent call last):
  File "/var/www/html/Python/temp_daily.py", line 60, in <module>
    with rasterio.open(f'./temp_daily_maps/{n}/{yest_year}_{yest_mon:02d}_{yest_day:02d}_{n}.tif') as src:
  File "/home/cherryle/.local/lib/python3.10/site-packages/rasterio/env.py", line 451, in wrapper
    return f(*args, **kwds)
  File "/home/cherryle/.local/lib/python3.10/site-packages/rasterio/__init__.py", line 304, in open
    dataset = DatasetReader(path, driver=driver, sharing=sharing, **kwargs)
  File "rasterio/_base.pyx", line 312, in rasterio._base.DatasetBase.__init__
rasterio.errors.RasterioIOError: './temp_daily_maps/mean/2024_07_13_mean.tif' not recognized as a supported file format.
Traceback (most recent call last):
  File "rasterio/_base.pyx", line 310, in rasterio._base.DatasetBase.__init__
  File "rasterio/_base.pyx", line 221, in rasterio._base.open_dataset
  File "rasterio/_err.pyx", line 221, in rasterio._err.exc_wrap_pointer
rasterio._err.CPLE_OpenFailedError: './temp_daily_maps/mean/2024_07_14_mean.tif' not recognized as a supported file format.

During handling of the above exception, another exception occurred:

Traceback (most recent call last):
  File "/var/www/html/Python/temp_daily.py", line 60, in <module>
    with rasterio.open(f'./temp_daily_maps/{n}/{yest_year}_{yest_mon:02d}_{yest_day:02d}_{n}.tif') as src:
  File "/home/cherryle/.local/lib/python3.10/site-packages/rasterio/env.py", line 451, in wrapper
    return f(*args, **kwds)
  File "/home/cherryle/.local/lib/python3.10/site-packages/rasterio/__init__.py", line 304, in open
    dataset = DatasetReader(path, driver=driver, sharing=sharing, **kwargs)
  File "rasterio/_base.pyx", line 312, in rasterio._base.DatasetBase.__init__
rasterio.errors.RasterioIOError: './temp_daily_maps/mean/2024_07_14_mean.tif' not recognized as a supported file format.
Traceback (most recent call last):
  File "rasterio/_base.pyx", line 310, in rasterio._base.DatasetBase.__init__
  File "rasterio/_base.pyx", line 221, in rasterio._base.open_dataset
  File "rasterio/_err.pyx", line 221, in rasterio._err.exc_wrap_pointer
rasterio._err.CPLE_OpenFailedError: './temp_daily_maps/mean/2024_07_15_mean.tif' not recognized as a supported file format.

During handling of the above exception, another exception occurred:

Traceback (most recent call last):
  File "/var/www/html/Python/temp_daily.py", line 60, in <module>
    with rasterio.open(f'./temp_daily_maps/{n}/{yest_year}_{yest_mon:02d}_{yest_day:02d}_{n}.tif') as src:
  File "/home/cherryle/.local/lib/python3.10/site-packages/rasterio/env.py", line 451, in wrapper
    return f(*args, **kwds)
  File "/home/cherryle/.local/lib/python3.10/site-packages/rasterio/__init__.py", line 304, in open
    dataset = DatasetReader(path, driver=driver, sharing=sharing, **kwargs)
  File "rasterio/_base.pyx", line 312, in rasterio._base.DatasetBase.__init__
rasterio.errors.RasterioIOError: './temp_daily_maps/mean/2024_07_15_mean.tif' not recognized as a supported file format.
Traceback (most recent call last):
  File "rasterio/_base.pyx", line 310, in rasterio._base.DatasetBase.__init__
  File "rasterio/_base.pyx", line 221, in rasterio._base.open_dataset
  File "rasterio/_err.pyx", line 221, in rasterio._err.exc_wrap_pointer
rasterio._err.CPLE_OpenFailedError: './temp_daily_maps/mean/2024_07_16_mean.tif' not recognized as a supported file format.

During handling of the above exception, another exception occurred:

Traceback (most recent call last):
  File "/var/www/html/Python/temp_daily.py", line 60, in <module>
    with rasterio.open(f'./temp_daily_maps/{n}/{yest_year}_{yest_mon:02d}_{yest_day:02d}_{n}.tif') as src:
  File "/home/cherryle/.local/lib/python3.10/site-packages/rasterio/env.py", line 451, in wrapper
    return f(*args, **kwds)
  File "/home/cherryle/.local/lib/python3.10/site-packages/rasterio/__init__.py", line 304, in open
    dataset = DatasetReader(path, driver=driver, sharing=sharing, **kwargs)
  File "rasterio/_base.pyx", line 312, in rasterio._base.DatasetBase.__init__
rasterio.errors.RasterioIOError: './temp_daily_maps/mean/2024_07_16_mean.tif' not recognized as a supported file format.
Traceback (most recent call last):
  File "rasterio/_base.pyx", line 310, in rasterio._base.DatasetBase.__init__
  File "rasterio/_base.pyx", line 221, in rasterio._base.open_dataset
  File "rasterio/_err.pyx", line 221, in rasterio._err.exc_wrap_pointer
rasterio._err.CPLE_OpenFailedError: './temp_daily_maps/mean/2024_07_22_mean.tif' not recognized as a supported file format.

During handling of the above exception, another exception occurred:

Traceback (most recent call last):
  File "/var/www/html/Python/temp_daily.py", line 60, in <module>
    with rasterio.open(f'./temp_daily_maps/{n}/{yest_year}_{yest_mon:02d}_{yest_day:02d}_{n}.tif') as src:
  File "/home/cherryle/.local/lib/python3.10/site-packages/rasterio/env.py", line 451, in wrapper
    return f(*args, **kwds)
  File "/home/cherryle/.local/lib/python3.10/site-packages/rasterio/__init__.py", line 304, in open
    dataset = DatasetReader(path, driver=driver, sharing=sharing, **kwargs)
  File "rasterio/_base.pyx", line 312, in rasterio._base.DatasetBase.__init__
rasterio.errors.RasterioIOError: './temp_daily_maps/mean/2024_07_22_mean.tif' not recognized as a supported file format.
Traceback (most recent call last):
  File "/usr/lib/python3/dist-packages/urllib3/connectionpool.py", line 700, in urlopen
    httplib_response = self._make_request(
  File "/usr/lib/python3/dist-packages/urllib3/connectionpool.py", line 446, in _make_request
    six.raise_from(e, None)
  File "<string>", line 3, in raise_from
  File "/usr/lib/python3/dist-packages/urllib3/connectionpool.py", line 441, in _make_request
    httplib_response = conn.getresponse()
  File "/usr/lib/python3.10/http/client.py", line 1375, in getresponse
    response.begin()
  File "/usr/lib/python3.10/http/client.py", line 318, in begin
    version, status, reason = self._read_status()
  File "/usr/lib/python3.10/http/client.py", line 287, in _read_status
    raise RemoteDisconnected("Remote end closed connection without"
http.client.RemoteDisconnected: Remote end closed connection without response

During handling of the above exception, another exception occurred:

Traceback (most recent call last):
  File "/usr/lib/python3/dist-packages/requests/adapters.py", line 439, in send
    resp = conn.urlopen(
  File "/usr/lib/python3/dist-packages/urllib3/connectionpool.py", line 756, in urlopen
    retries = retries.increment(
  File "/usr/lib/python3/dist-packages/urllib3/util/retry.py", line 532, in increment
    raise six.reraise(type(error), error, _stacktrace)
  File "/usr/lib/python3/dist-packages/six.py", line 718, in reraise
    raise value.with_traceback(tb)
  File "/usr/lib/python3/dist-packages/urllib3/connectionpool.py", line 700, in urlopen
    httplib_response = self._make_request(
  File "/usr/lib/python3/dist-packages/urllib3/connectionpool.py", line 446, in _make_request
    six.raise_from(e, None)
  File "<string>", line 3, in raise_from
  File "/usr/lib/python3/dist-packages/urllib3/connectionpool.py", line 441, in _make_request
    httplib_response = conn.getresponse()
  File "/usr/lib/python3.10/http/client.py", line 1375, in getresponse
    response.begin()
  File "/usr/lib/python3.10/http/client.py", line 318, in begin
    version, status, reason = self._read_status()
  File "/usr/lib/python3.10/http/client.py", line 287, in _read_status
    raise RemoteDisconnected("Remote end closed connection without"
urllib3.exceptions.ProtocolError: ('Connection aborted.', RemoteDisconnected('Remote end closed connection without response'))

During handling of the above exception, another exception occurred:

Traceback (most recent call last):
  File "/var/www/html/Python/temp_daily.py", line 28, in <module>
    r = requests.get(mean_url)
  File "/usr/lib/python3/dist-packages/requests/api.py", line 76, in get
    return request('get', url, params=params, **kwargs)
  File "/usr/lib/python3/dist-packages/requests/api.py", line 61, in request
    return session.request(method=method, url=url, **kwargs)
  File "/usr/lib/python3/dist-packages/requests/sessions.py", line 544, in request
    resp = self.send(prep, **send_kwargs)
  File "/usr/lib/python3/dist-packages/requests/sessions.py", line 657, in send
    r = adapter.send(request, **kwargs)
  File "/usr/lib/python3/dist-packages/requests/adapters.py", line 498, in send
    raise ConnectionError(err, request=request)
requests.exceptions.ConnectionError: ('Connection aborted.', RemoteDisconnected('Remote end closed connection without response'))
Traceback (most recent call last):
  File "rasterio/_base.pyx", line 310, in rasterio._base.DatasetBase.__init__
  File "rasterio/_base.pyx", line 221, in rasterio._base.open_dataset
  File "rasterio/_err.pyx", line 221, in rasterio._err.exc_wrap_pointer
rasterio._err.CPLE_OpenFailedError: './temp_daily_maps/mean/2024_09_15_mean.tif' not recognized as a supported file format.

During handling of the above exception, another exception occurred:

Traceback (most recent call last):
  File "/var/www/html/Python/temp_daily.py", line 60, in <module>
    with rasterio.open(f'./temp_daily_maps/{n}/{yest_year}_{yest_mon:02d}_{yest_day:02d}_{n}.tif') as src:
  File "/home/cherryle/.local/lib/python3.10/site-packages/rasterio/env.py", line 451, in wrapper
    return f(*args, **kwds)
  File "/home/cherryle/.local/lib/python3.10/site-packages/rasterio/__init__.py", line 304, in open
    dataset = DatasetReader(path, driver=driver, sharing=sharing, **kwargs)
  File "rasterio/_base.pyx", line 312, in rasterio._base.DatasetBase.__init__
rasterio.errors.RasterioIOError: './temp_daily_maps/mean/2024_09_15_mean.tif' not recognized as a supported file format.
Traceback (most recent call last):
  File "rasterio/_base.pyx", line 310, in rasterio._base.DatasetBase.__init__
  File "rasterio/_base.pyx", line 221, in rasterio._base.open_dataset
  File "rasterio/_err.pyx", line 221, in rasterio._err.exc_wrap_pointer
rasterio._err.CPLE_OpenFailedError: './temp_daily_maps/mean/2024_11_06_mean.tif' not recognized as a supported file format.

During handling of the above exception, another exception occurred:

Traceback (most recent call last):
  File "/var/www/html/Python/temp_daily.py", line 60, in <module>
    with rasterio.open(f'./temp_daily_maps/{n}/{yest_year}_{yest_mon:02d}_{yest_day:02d}_{n}.tif') as src:
  File "/home/cherryle/.local/lib/python3.10/site-packages/rasterio/env.py", line 451, in wrapper
    return f(*args, **kwds)
  File "/home/cherryle/.local/lib/python3.10/site-packages/rasterio/__init__.py", line 304, in open
    dataset = DatasetReader(path, driver=driver, sharing=sharing, **kwargs)
  File "rasterio/_base.pyx", line 312, in rasterio._base.DatasetBase.__init__
rasterio.errors.RasterioIOError: './temp_daily_maps/mean/2024_11_06_mean.tif' not recognized as a supported file format.
Traceback (most recent call last):
  File "rasterio/_base.pyx", line 310, in rasterio._base.DatasetBase.__init__
  File "rasterio/_base.pyx", line 221, in rasterio._base.open_dataset
  File "rasterio/_err.pyx", line 221, in rasterio._err.exc_wrap_pointer
rasterio._err.CPLE_OpenFailedError: './temp_daily_maps/mean/2024_12_15_mean.tif' not recognized as a supported file format.

During handling of the above exception, another exception occurred:

Traceback (most recent call last):
  File "/var/www/html/Python/temp_daily.py", line 60, in <module>
    with rasterio.open(f'./temp_daily_maps/{n}/{yest_year}_{yest_mon:02d}_{yest_day:02d}_{n}.tif') as src:
  File "/home/cherryle/.local/lib/python3.10/site-packages/rasterio/env.py", line 451, in wrapper
    return f(*args, **kwds)
  File "/home/cherryle/.local/lib/python3.10/site-packages/rasterio/__init__.py", line 304, in open
    dataset = DatasetReader(path, driver=driver, sharing=sharing, **kwargs)
  File "rasterio/_base.pyx", line 312, in rasterio._base.DatasetBase.__init__
rasterio.errors.RasterioIOError: './temp_daily_maps/mean/2024_12_15_mean.tif' not recognized as a supported file format.
Traceback (most recent call last):
  File "/usr/lib/python3/dist-packages/urllib3/connectionpool.py", line 700, in urlopen
    httplib_response = self._make_request(
  File "/usr/lib/python3/dist-packages/urllib3/connectionpool.py", line 383, in _make_request
    self._validate_conn(conn)
  File "/usr/lib/python3/dist-packages/urllib3/connectionpool.py", line 1017, in _validate_conn
    conn.connect()
  File "/usr/lib/python3/dist-packages/urllib3/connection.py", line 411, in connect
    self.sock = ssl_wrap_socket(
  File "/usr/lib/python3/dist-packages/urllib3/util/ssl_.py", line 449, in ssl_wrap_socket
    ssl_sock = _ssl_wrap_socket_impl(
  File "/usr/lib/python3/dist-packages/urllib3/util/ssl_.py", line 493, in _ssl_wrap_socket_impl
    return ssl_context.wrap_socket(sock, server_hostname=server_hostname)
  File "/usr/lib/python3.10/ssl.py", line 513, in wrap_socket
    return self.sslsocket_class._create(
  File "/usr/lib/python3.10/ssl.py", line 1100, in _create
    self.do_handshake()
  File "/usr/lib/python3.10/ssl.py", line 1371, in do_handshake
    self._sslobj.do_handshake()
ssl.SSLEOFError: [SSL: UNEXPECTED_EOF_WHILE_READING] EOF occurred in violation of protocol (_ssl.c:1007)

During handling of the above exception, another exception occurred:

Traceback (most recent call last):
  File "/usr/lib/python3/dist-packages/requests/adapters.py", line 439, in send
    resp = conn.urlopen(
  File "/usr/lib/python3/dist-packages/urllib3/connectionpool.py", line 756, in urlopen
    retries = retries.increment(
  File "/usr/lib/python3/dist-packages/urllib3/util/retry.py", line 576, in increment
    raise MaxRetryError(_pool, url, error or ResponseError(cause))
urllib3.exceptions.MaxRetryError: HTTPSConnectionPool(host='ikeauth.its.hawaii.edu', port=443): Max retries exceeded with url: /files/v2/download/public/system/ikewai-annotated-data/HCDP/production/temperature/mean/day/statewide/data_map/2025/01/temperature_mean_day_statewide_data_map_2025_01_10.tif (Caused by SSLError(SSLEOFError(8, '[SSL: UNEXPECTED_EOF_WHILE_READING] EOF occurred in violation of protocol (_ssl.c:1007)')))

During handling of the above exception, another exception occurred:

Traceback (most recent call last):
  File "/var/www/html/Python/temp_daily.py", line 28, in <module>
    r = requests.get(mean_url)
  File "/usr/lib/python3/dist-packages/requests/api.py", line 76, in get
    return request('get', url, params=params, **kwargs)
  File "/usr/lib/python3/dist-packages/requests/api.py", line 61, in request
    return session.request(method=method, url=url, **kwargs)
  File "/usr/lib/python3/dist-packages/requests/sessions.py", line 544, in request
    resp = self.send(prep, **send_kwargs)
  File "/usr/lib/python3/dist-packages/requests/sessions.py", line 657, in send
    r = adapter.send(request, **kwargs)
  File "/usr/lib/python3/dist-packages/requests/adapters.py", line 514, in send
    raise SSLError(e, request=request)
requests.exceptions.SSLError: HTTPSConnectionPool(host='ikeauth.its.hawaii.edu', port=443): Max retries exceeded with url: /files/v2/download/public/system/ikewai-annotated-data/HCDP/production/temperature/mean/day/statewide/data_map/2025/01/temperature_mean_day_statewide_data_map_2025_01_10.tif (Caused by SSLError(SSLEOFError(8, '[SSL: UNEXPECTED_EOF_WHILE_READING] EOF occurred in violation of protocol (_ssl.c:1007)')))
Traceback (most recent call last):
  File "/usr/lib/python3/dist-packages/urllib3/connectionpool.py", line 700, in urlopen
    httplib_response = self._make_request(
  File "/usr/lib/python3/dist-packages/urllib3/connectionpool.py", line 383, in _make_request
    self._validate_conn(conn)
  File "/usr/lib/python3/dist-packages/urllib3/connectionpool.py", line 1017, in _validate_conn
    conn.connect()
  File "/usr/lib/python3/dist-packages/urllib3/connection.py", line 411, in connect
    self.sock = ssl_wrap_socket(
  File "/usr/lib/python3/dist-packages/urllib3/util/ssl_.py", line 449, in ssl_wrap_socket
    ssl_sock = _ssl_wrap_socket_impl(
  File "/usr/lib/python3/dist-packages/urllib3/util/ssl_.py", line 493, in _ssl_wrap_socket_impl
    return ssl_context.wrap_socket(sock, server_hostname=server_hostname)
  File "/usr/lib/python3.10/ssl.py", line 513, in wrap_socket
    return self.sslsocket_class._create(
  File "/usr/lib/python3.10/ssl.py", line 1100, in _create
    self.do_handshake()
  File "/usr/lib/python3.10/ssl.py", line 1371, in do_handshake
    self._sslobj.do_handshake()
ssl.SSLEOFError: [SSL: UNEXPECTED_EOF_WHILE_READING] EOF occurred in violation of protocol (_ssl.c:1007)

During handling of the above exception, another exception occurred:

Traceback (most recent call last):
  File "/usr/lib/python3/dist-packages/requests/adapters.py", line 439, in send
    resp = conn.urlopen(
  File "/usr/lib/python3/dist-packages/urllib3/connectionpool.py", line 756, in urlopen
    retries = retries.increment(
  File "/usr/lib/python3/dist-packages/urllib3/util/retry.py", line 576, in increment
    raise MaxRetryError(_pool, url, error or ResponseError(cause))
urllib3.exceptions.MaxRetryError: HTTPSConnectionPool(host='ikeauth.its.hawaii.edu', port=443): Max retries exceeded with url: /files/v2/download/public/system/ikewai-annotated-data/HCDP/production/temperature/mean/day/statewide/data_map/2025/01/temperature_mean_day_statewide_data_map_2025_01_11.tif (Caused by SSLError(SSLEOFError(8, '[SSL: UNEXPECTED_EOF_WHILE_READING] EOF occurred in violation of protocol (_ssl.c:1007)')))

During handling of the above exception, another exception occurred:

Traceback (most recent call last):
  File "/var/www/html/Python/temp_daily.py", line 28, in <module>
    r = requests.get(mean_url)
  File "/usr/lib/python3/dist-packages/requests/api.py", line 76, in get
    return request('get', url, params=params, **kwargs)
  File "/usr/lib/python3/dist-packages/requests/api.py", line 61, in request
    return session.request(method=method, url=url, **kwargs)
  File "/usr/lib/python3/dist-packages/requests/sessions.py", line 544, in request
    resp = self.send(prep, **send_kwargs)
  File "/usr/lib/python3/dist-packages/requests/sessions.py", line 657, in send
    r = adapter.send(request, **kwargs)
  File "/usr/lib/python3/dist-packages/requests/adapters.py", line 514, in send
    raise SSLError(e, request=request)
requests.exceptions.SSLError: HTTPSConnectionPool(host='ikeauth.its.hawaii.edu', port=443): Max retries exceeded with url: /files/v2/download/public/system/ikewai-annotated-data/HCDP/production/temperature/mean/day/statewide/data_map/2025/01/temperature_mean_day_statewide_data_map_2025_01_11.tif (Caused by SSLError(SSLEOFError(8, '[SSL: UNEXPECTED_EOF_WHILE_READING] EOF occurred in violation of protocol (_ssl.c:1007)')))
Traceback (most recent call last):
  File "/usr/lib/python3/dist-packages/urllib3/connectionpool.py", line 700, in urlopen
    httplib_response = self._make_request(
  File "/usr/lib/python3/dist-packages/urllib3/connectionpool.py", line 383, in _make_request
    self._validate_conn(conn)
  File "/usr/lib/python3/dist-packages/urllib3/connectionpool.py", line 1017, in _validate_conn
    conn.connect()
  File "/usr/lib/python3/dist-packages/urllib3/connection.py", line 411, in connect
    self.sock = ssl_wrap_socket(
  File "/usr/lib/python3/dist-packages/urllib3/util/ssl_.py", line 449, in ssl_wrap_socket
    ssl_sock = _ssl_wrap_socket_impl(
  File "/usr/lib/python3/dist-packages/urllib3/util/ssl_.py", line 493, in _ssl_wrap_socket_impl
    return ssl_context.wrap_socket(sock, server_hostname=server_hostname)
  File "/usr/lib/python3.10/ssl.py", line 513, in wrap_socket
    return self.sslsocket_class._create(
  File "/usr/lib/python3.10/ssl.py", line 1100, in _create
    self.do_handshake()
  File "/usr/lib/python3.10/ssl.py", line 1371, in do_handshake
    self._sslobj.do_handshake()
ssl.SSLEOFError: [SSL: UNEXPECTED_EOF_WHILE_READING] EOF occurred in violation of protocol (_ssl.c:1007)

During handling of the above exception, another exception occurred:

Traceback (most recent call last):
  File "/usr/lib/python3/dist-packages/requests/adapters.py", line 439, in send
    resp = conn.urlopen(
  File "/usr/lib/python3/dist-packages/urllib3/connectionpool.py", line 756, in urlopen
    retries = retries.increment(
  File "/usr/lib/python3/dist-packages/urllib3/util/retry.py", line 576, in increment
    raise MaxRetryError(_pool, url, error or ResponseError(cause))
urllib3.exceptions.MaxRetryError: HTTPSConnectionPool(host='ikeauth.its.hawaii.edu', port=443): Max retries exceeded with url: /files/v2/download/public/system/ikewai-annotated-data/HCDP/production/temperature/mean/day/statewide/data_map/2025/01/temperature_mean_day_statewide_data_map_2025_01_12.tif (Caused by SSLError(SSLEOFError(8, '[SSL: UNEXPECTED_EOF_WHILE_READING] EOF occurred in violation of protocol (_ssl.c:1007)')))

During handling of the above exception, another exception occurred:

Traceback (most recent call last):
  File "/var/www/html/Python/temp_daily.py", line 28, in <module>
    r = requests.get(mean_url)
  File "/usr/lib/python3/dist-packages/requests/api.py", line 76, in get
    return request('get', url, params=params, **kwargs)
  File "/usr/lib/python3/dist-packages/requests/api.py", line 61, in request
    return session.request(method=method, url=url, **kwargs)
  File "/usr/lib/python3/dist-packages/requests/sessions.py", line 544, in request
    resp = self.send(prep, **send_kwargs)
  File "/usr/lib/python3/dist-packages/requests/sessions.py", line 657, in send
    r = adapter.send(request, **kwargs)
  File "/usr/lib/python3/dist-packages/requests/adapters.py", line 514, in send
    raise SSLError(e, request=request)
requests.exceptions.SSLError: HTTPSConnectionPool(host='ikeauth.its.hawaii.edu', port=443): Max retries exceeded with url: /files/v2/download/public/system/ikewai-annotated-data/HCDP/production/temperature/mean/day/statewide/data_map/2025/01/temperature_mean_day_statewide_data_map_2025_01_12.tif (Caused by SSLError(SSLEOFError(8, '[SSL: UNEXPECTED_EOF_WHILE_READING] EOF occurred in violation of protocol (_ssl.c:1007)')))
Traceback (most recent call last):
  File "/usr/lib/python3/dist-packages/urllib3/connectionpool.py", line 700, in urlopen
    httplib_response = self._make_request(
  File "/usr/lib/python3/dist-packages/urllib3/connectionpool.py", line 383, in _make_request
    self._validate_conn(conn)
  File "/usr/lib/python3/dist-packages/urllib3/connectionpool.py", line 1017, in _validate_conn
    conn.connect()
  File "/usr/lib/python3/dist-packages/urllib3/connection.py", line 411, in connect
    self.sock = ssl_wrap_socket(
  File "/usr/lib/python3/dist-packages/urllib3/util/ssl_.py", line 449, in ssl_wrap_socket
    ssl_sock = _ssl_wrap_socket_impl(
  File "/usr/lib/python3/dist-packages/urllib3/util/ssl_.py", line 493, in _ssl_wrap_socket_impl
    return ssl_context.wrap_socket(sock, server_hostname=server_hostname)
  File "/usr/lib/python3.10/ssl.py", line 513, in wrap_socket
    return self.sslsocket_class._create(
  File "/usr/lib/python3.10/ssl.py", line 1100, in _create
    self.do_handshake()
  File "/usr/lib/python3.10/ssl.py", line 1371, in do_handshake
    self._sslobj.do_handshake()
ssl.SSLEOFError: [SSL: UNEXPECTED_EOF_WHILE_READING] EOF occurred in violation of protocol (_ssl.c:1007)

During handling of the above exception, another exception occurred:

Traceback (most recent call last):
  File "/usr/lib/python3/dist-packages/requests/adapters.py", line 439, in send
    resp = conn.urlopen(
  File "/usr/lib/python3/dist-packages/urllib3/connectionpool.py", line 756, in urlopen
    retries = retries.increment(
  File "/usr/lib/python3/dist-packages/urllib3/util/retry.py", line 576, in increment
    raise MaxRetryError(_pool, url, error or ResponseError(cause))
urllib3.exceptions.MaxRetryError: HTTPSConnectionPool(host='ikeauth.its.hawaii.edu', port=443): Max retries exceeded with url: /files/v2/download/public/system/ikewai-annotated-data/HCDP/production/temperature/mean/day/statewide/data_map/2025/01/temperature_mean_day_statewide_data_map_2025_01_13.tif (Caused by SSLError(SSLEOFError(8, '[SSL: UNEXPECTED_EOF_WHILE_READING] EOF occurred in violation of protocol (_ssl.c:1007)')))

During handling of the above exception, another exception occurred:

Traceback (most recent call last):
  File "/var/www/html/Python/temp_daily.py", line 28, in <module>
    r = requests.get(mean_url)
  File "/usr/lib/python3/dist-packages/requests/api.py", line 76, in get
    return request('get', url, params=params, **kwargs)
  File "/usr/lib/python3/dist-packages/requests/api.py", line 61, in request
    return session.request(method=method, url=url, **kwargs)
  File "/usr/lib/python3/dist-packages/requests/sessions.py", line 544, in request
    resp = self.send(prep, **send_kwargs)
  File "/usr/lib/python3/dist-packages/requests/sessions.py", line 657, in send
    r = adapter.send(request, **kwargs)
  File "/usr/lib/python3/dist-packages/requests/adapters.py", line 514, in send
    raise SSLError(e, request=request)
requests.exceptions.SSLError: HTTPSConnectionPool(host='ikeauth.its.hawaii.edu', port=443): Max retries exceeded with url: /files/v2/download/public/system/ikewai-annotated-data/HCDP/production/temperature/mean/day/statewide/data_map/2025/01/temperature_mean_day_statewide_data_map_2025_01_13.tif (Caused by SSLError(SSLEOFError(8, '[SSL: UNEXPECTED_EOF_WHILE_READING] EOF occurred in violation of protocol (_ssl.c:1007)')))
Traceback (most recent call last):
  File "/usr/lib/python3/dist-packages/urllib3/connection.py", line 169, in _new_conn
    conn = connection.create_connection(
  File "/usr/lib/python3/dist-packages/urllib3/util/connection.py", line 73, in create_connection
    for res in socket.getaddrinfo(host, port, family, socket.SOCK_STREAM):
  File "/usr/lib/python3.10/socket.py", line 955, in getaddrinfo
    for res in _socket.getaddrinfo(host, port, family, type, proto, flags):
socket.gaierror: [Errno -3] Temporary failure in name resolution

During handling of the above exception, another exception occurred:

Traceback (most recent call last):
  File "/usr/lib/python3/dist-packages/urllib3/connectionpool.py", line 700, in urlopen
    httplib_response = self._make_request(
  File "/usr/lib/python3/dist-packages/urllib3/connectionpool.py", line 383, in _make_request
    self._validate_conn(conn)
  File "/usr/lib/python3/dist-packages/urllib3/connectionpool.py", line 1017, in _validate_conn
    conn.connect()
  File "/usr/lib/python3/dist-packages/urllib3/connection.py", line 353, in connect
    conn = self._new_conn()
  File "/usr/lib/python3/dist-packages/urllib3/connection.py", line 181, in _new_conn
    raise NewConnectionError(
urllib3.exceptions.NewConnectionError: <urllib3.connection.HTTPSConnection object at 0x7f2304a9c550>: Failed to establish a new connection: [Errno -3] Temporary failure in name resolution

During handling of the above exception, another exception occurred:

Traceback (most recent call last):
  File "/usr/lib/python3/dist-packages/requests/adapters.py", line 439, in send
    resp = conn.urlopen(
  File "/usr/lib/python3/dist-packages/urllib3/connectionpool.py", line 756, in urlopen
    retries = retries.increment(
  File "/usr/lib/python3/dist-packages/urllib3/util/retry.py", line 576, in increment
    raise MaxRetryError(_pool, url, error or ResponseError(cause))
urllib3.exceptions.MaxRetryError: HTTPSConnectionPool(host='ikeauth.its.hawaii.edu', port=443): Max retries exceeded with url: /files/v2/download/public/system/ikewai-annotated-data/HCDP/production/temperature/mean/day/statewide/data_map/2025/02/temperature_mean_day_statewide_data_map_2025_02_06.tif (Caused by NewConnectionError('<urllib3.connection.HTTPSConnection object at 0x7f2304a9c550>: Failed to establish a new connection: [Errno -3] Temporary failure in name resolution'))

During handling of the above exception, another exception occurred:

Traceback (most recent call last):
  File "/var/www/html/Python/temp_daily.py", line 28, in <module>
    r = requests.get(mean_url)
  File "/usr/lib/python3/dist-packages/requests/api.py", line 76, in get
    return request('get', url, params=params, **kwargs)
  File "/usr/lib/python3/dist-packages/requests/api.py", line 61, in request
    return session.request(method=method, url=url, **kwargs)
  File "/usr/lib/python3/dist-packages/requests/sessions.py", line 544, in request
    resp = self.send(prep, **send_kwargs)
  File "/usr/lib/python3/dist-packages/requests/sessions.py", line 657, in send
    r = adapter.send(request, **kwargs)
  File "/usr/lib/python3/dist-packages/requests/adapters.py", line 516, in send
    raise ConnectionError(e, request=request)
requests.exceptions.ConnectionError: HTTPSConnectionPool(host='ikeauth.its.hawaii.edu', port=443): Max retries exceeded with url: /files/v2/download/public/system/ikewai-annotated-data/HCDP/production/temperature/mean/day/statewide/data_map/2025/02/temperature_mean_day_statewide_data_map_2025_02_06.tif (Caused by NewConnectionError('<urllib3.connection.HTTPSConnection object at 0x7f2304a9c550>: Failed to establish a new connection: [Errno -3] Temporary failure in name resolution'))
Traceback (most recent call last):
  File "/usr/lib/python3/dist-packages/urllib3/connection.py", line 169, in _new_conn
    conn = connection.create_connection(
  File "/usr/lib/python3/dist-packages/urllib3/util/connection.py", line 73, in create_connection
    for res in socket.getaddrinfo(host, port, family, socket.SOCK_STREAM):
  File "/usr/lib/python3.10/socket.py", line 955, in getaddrinfo
    for res in _socket.getaddrinfo(host, port, family, type, proto, flags):
socket.gaierror: [Errno -3] Temporary failure in name resolution

During handling of the above exception, another exception occurred:

Traceback (most recent call last):
  File "/usr/lib/python3/dist-packages/urllib3/connectionpool.py", line 700, in urlopen
    httplib_response = self._make_request(
  File "/usr/lib/python3/dist-packages/urllib3/connectionpool.py", line 383, in _make_request
    self._validate_conn(conn)
  File "/usr/lib/python3/dist-packages/urllib3/connectionpool.py", line 1017, in _validate_conn
    conn.connect()
  File "/usr/lib/python3/dist-packages/urllib3/connection.py", line 353, in connect
    conn = self._new_conn()
  File "/usr/lib/python3/dist-packages/urllib3/connection.py", line 181, in _new_conn
    raise NewConnectionError(
urllib3.exceptions.NewConnectionError: <urllib3.connection.HTTPSConnection object at 0x7f2dd0108550>: Failed to establish a new connection: [Errno -3] Temporary failure in name resolution

During handling of the above exception, another exception occurred:

Traceback (most recent call last):
  File "/usr/lib/python3/dist-packages/requests/adapters.py", line 439, in send
    resp = conn.urlopen(
  File "/usr/lib/python3/dist-packages/urllib3/connectionpool.py", line 756, in urlopen
    retries = retries.increment(
  File "/usr/lib/python3/dist-packages/urllib3/util/retry.py", line 576, in increment
    raise MaxRetryError(_pool, url, error or ResponseError(cause))
urllib3.exceptions.MaxRetryError: HTTPSConnectionPool(host='ikeauth.its.hawaii.edu', port=443): Max retries exceeded with url: /files/v2/download/public/system/ikewai-annotated-data/HCDP/production/temperature/mean/day/statewide/data_map/2025/02/temperature_mean_day_statewide_data_map_2025_02_07.tif (Caused by NewConnectionError('<urllib3.connection.HTTPSConnection object at 0x7f2dd0108550>: Failed to establish a new connection: [Errno -3] Temporary failure in name resolution'))

During handling of the above exception, another exception occurred:

Traceback (most recent call last):
  File "/var/www/html/Python/temp_daily.py", line 28, in <module>
    r = requests.get(mean_url)
  File "/usr/lib/python3/dist-packages/requests/api.py", line 76, in get
    return request('get', url, params=params, **kwargs)
  File "/usr/lib/python3/dist-packages/requests/api.py", line 61, in request
    return session.request(method=method, url=url, **kwargs)
  File "/usr/lib/python3/dist-packages/requests/sessions.py", line 544, in request
    resp = self.send(prep, **send_kwargs)
  File "/usr/lib/python3/dist-packages/requests/sessions.py", line 657, in send
    r = adapter.send(request, **kwargs)
  File "/usr/lib/python3/dist-packages/requests/adapters.py", line 516, in send
    raise ConnectionError(e, request=request)
requests.exceptions.ConnectionError: HTTPSConnectionPool(host='ikeauth.its.hawaii.edu', port=443): Max retries exceeded with url: /files/v2/download/public/system/ikewai-annotated-data/HCDP/production/temperature/mean/day/statewide/data_map/2025/02/temperature_mean_day_statewide_data_map_2025_02_07.tif (Caused by NewConnectionError('<urllib3.connection.HTTPSConnection object at 0x7f2dd0108550>: Failed to establish a new connection: [Errno -3] Temporary failure in name resolution'))
Traceback (most recent call last):
  File "/usr/lib/python3/dist-packages/urllib3/connection.py", line 169, in _new_conn
    conn = connection.create_connection(
  File "/usr/lib/python3/dist-packages/urllib3/util/connection.py", line 96, in create_connection
    raise err
  File "/usr/lib/python3/dist-packages/urllib3/util/connection.py", line 86, in create_connection
    sock.connect(sa)
TimeoutError: [Errno 110] Connection timed out

During handling of the above exception, another exception occurred:

Traceback (most recent call last):
  File "/usr/lib/python3/dist-packages/urllib3/connectionpool.py", line 700, in urlopen
    httplib_response = self._make_request(
  File "/usr/lib/python3/dist-packages/urllib3/connectionpool.py", line 383, in _make_request
    self._validate_conn(conn)
  File "/usr/lib/python3/dist-packages/urllib3/connectionpool.py", line 1017, in _validate_conn
    conn.connect()
  File "/usr/lib/python3/dist-packages/urllib3/connection.py", line 353, in connect
    conn = self._new_conn()
  File "/usr/lib/python3/dist-packages/urllib3/connection.py", line 174, in _new_conn
    raise ConnectTimeoutError(
urllib3.exceptions.ConnectTimeoutError: (<urllib3.connection.HTTPSConnection object at 0x7efe6afe0af0>, 'Connection to ikeauth.its.hawaii.edu timed out. (connect timeout=None)')

During handling of the above exception, another exception occurred:

Traceback (most recent call last):
  File "/usr/lib/python3/dist-packages/requests/adapters.py", line 439, in send
    resp = conn.urlopen(
  File "/usr/lib/python3/dist-packages/urllib3/connectionpool.py", line 756, in urlopen
    retries = retries.increment(
  File "/usr/lib/python3/dist-packages/urllib3/util/retry.py", line 576, in increment
    raise MaxRetryError(_pool, url, error or ResponseError(cause))
urllib3.exceptions.MaxRetryError: HTTPSConnectionPool(host='ikeauth.its.hawaii.edu', port=443): Max retries exceeded with url: /files/v2/download/public/system/ikewai-annotated-data/HCDP/production/temperature/min/day/statewide/data_map/2025/02/temperature_min_day_statewide_data_map_2025_02_12.tif (Caused by ConnectTimeoutError(<urllib3.connection.HTTPSConnection object at 0x7efe6afe0af0>, 'Connection to ikeauth.its.hawaii.edu timed out. (connect timeout=None)'))

During handling of the above exception, another exception occurred:

Traceback (most recent call last):
  File "/var/www/html/Python/temp_daily.py", line 39, in <module>
    r = requests.get(min_url)
  File "/usr/lib/python3/dist-packages/requests/api.py", line 76, in get
    return request('get', url, params=params, **kwargs)
  File "/usr/lib/python3/dist-packages/requests/api.py", line 61, in request
    return session.request(method=method, url=url, **kwargs)
  File "/usr/lib/python3/dist-packages/requests/sessions.py", line 544, in request
    resp = self.send(prep, **send_kwargs)
  File "/usr/lib/python3/dist-packages/requests/sessions.py", line 657, in send
    r = adapter.send(request, **kwargs)
  File "/usr/lib/python3/dist-packages/requests/adapters.py", line 504, in send
    raise ConnectTimeout(e, request=request)
requests.exceptions.ConnectTimeout: HTTPSConnectionPool(host='ikeauth.its.hawaii.edu', port=443): Max retries exceeded with url: /files/v2/download/public/system/ikewai-annotated-data/HCDP/production/temperature/min/day/statewide/data_map/2025/02/temperature_min_day_statewide_data_map_2025_02_12.tif (Caused by ConnectTimeoutError(<urllib3.connection.HTTPSConnection object at 0x7efe6afe0af0>, 'Connection to ikeauth.its.hawaii.edu timed out. (connect timeout=None)'))
