Traceback (most recent call last):
  File "rasterio/_base.pyx", line 310, in rasterio._base.DatasetBase.__init__
  File "rasterio/_base.pyx", line 221, in rasterio._base.open_dataset
  File "rasterio/_err.pyx", line 221, in rasterio._err.exc_wrap_pointer
rasterio._err.CPLE_OpenFailedError: './temp_daily_maps/mean/2024_02_06_mean.tif' not recognized as a supported file format.

During handling of the above exception, another exception occurred:

Traceback (most recent call last):
  File "/var/www/html/Python/temp_daily.py", line 60, in <module>
    with rasterio.open(f'./temp_daily_maps/{n}/{yest_year}_{yest_mon:02d}_{yest_day:02d}_{n}.tif') as src:
  File "/home/cherryle/.local/lib/python3.10/site-packages/rasterio/env.py", line 451, in wrapper
    return f(*args, **kwds)
  File "/home/cherryle/.local/lib/python3.10/site-packages/rasterio/__init__.py", line 304, in open
    dataset = DatasetReader(path, driver=driver, sharing=sharing, **kwargs)
  File "rasterio/_base.pyx", line 312, in rasterio._base.DatasetBase.__init__
rasterio.errors.RasterioIOError: './temp_daily_maps/mean/2024_02_06_mean.tif' not recognized as a supported file format.
Traceback (most recent call last):
  File "rasterio/_base.pyx", line 310, in rasterio._base.DatasetBase.__init__
  File "rasterio/_base.pyx", line 221, in rasterio._base.open_dataset
  File "rasterio/_err.pyx", line 221, in rasterio._err.exc_wrap_pointer
rasterio._err.CPLE_OpenFailedError: './temp_daily_maps/mean/2024_02_07_mean.tif' not recognized as a supported file format.

During handling of the above exception, another exception occurred:

Traceback (most recent call last):
  File "/var/www/html/Python/temp_daily.py", line 60, in <module>
    with rasterio.open(f'./temp_daily_maps/{n}/{yest_year}_{yest_mon:02d}_{yest_day:02d}_{n}.tif') as src:
  File "/home/cherryle/.local/lib/python3.10/site-packages/rasterio/env.py", line 451, in wrapper
    return f(*args, **kwds)
  File "/home/cherryle/.local/lib/python3.10/site-packages/rasterio/__init__.py", line 304, in open
    dataset = DatasetReader(path, driver=driver, sharing=sharing, **kwargs)
  File "rasterio/_base.pyx", line 312, in rasterio._base.DatasetBase.__init__
rasterio.errors.RasterioIOError: './temp_daily_maps/mean/2024_02_07_mean.tif' not recognized as a supported file format.
Traceback (most recent call last):
  File "rasterio/_base.pyx", line 310, in rasterio._base.DatasetBase.__init__
  File "rasterio/_base.pyx", line 221, in rasterio._base.open_dataset
  File "rasterio/_err.pyx", line 221, in rasterio._err.exc_wrap_pointer
rasterio._err.CPLE_OpenFailedError: './temp_daily_maps/mean/2024_02_08_mean.tif' not recognized as a supported file format.

During handling of the above exception, another exception occurred:

Traceback (most recent call last):
  File "/var/www/html/Python/temp_daily.py", line 60, in <module>
    with rasterio.open(f'./temp_daily_maps/{n}/{yest_year}_{yest_mon:02d}_{yest_day:02d}_{n}.tif') as src:
  File "/home/cherryle/.local/lib/python3.10/site-packages/rasterio/env.py", line 451, in wrapper
    return f(*args, **kwds)
  File "/home/cherryle/.local/lib/python3.10/site-packages/rasterio/__init__.py", line 304, in open
    dataset = DatasetReader(path, driver=driver, sharing=sharing, **kwargs)
  File "rasterio/_base.pyx", line 312, in rasterio._base.DatasetBase.__init__
rasterio.errors.RasterioIOError: './temp_daily_maps/mean/2024_02_08_mean.tif' not recognized as a supported file format.
Traceback (most recent call last):
  File "rasterio/_base.pyx", line 310, in rasterio._base.DatasetBase.__init__
  File "rasterio/_base.pyx", line 221, in rasterio._base.open_dataset
  File "rasterio/_err.pyx", line 221, in rasterio._err.exc_wrap_pointer
rasterio._err.CPLE_OpenFailedError: './temp_daily_maps/mean/2024_02_15_mean.tif' not recognized as a supported file format.

During handling of the above exception, another exception occurred:

Traceback (most recent call last):
  File "/var/www/html/Python/temp_daily.py", line 60, in <module>
    with rasterio.open(f'./temp_daily_maps/{n}/{yest_year}_{yest_mon:02d}_{yest_day:02d}_{n}.tif') as src:
  File "/home/cherryle/.local/lib/python3.10/site-packages/rasterio/env.py", line 451, in wrapper
    return f(*args, **kwds)
  File "/home/cherryle/.local/lib/python3.10/site-packages/rasterio/__init__.py", line 304, in open
    dataset = DatasetReader(path, driver=driver, sharing=sharing, **kwargs)
  File "rasterio/_base.pyx", line 312, in rasterio._base.DatasetBase.__init__
rasterio.errors.RasterioIOError: './temp_daily_maps/mean/2024_02_15_mean.tif' not recognized as a supported file format.
Traceback (most recent call last):
  File "rasterio/_base.pyx", line 310, in rasterio._base.DatasetBase.__init__
  File "rasterio/_base.pyx", line 221, in rasterio._base.open_dataset
  File "rasterio/_err.pyx", line 221, in rasterio._err.exc_wrap_pointer
rasterio._err.CPLE_OpenFailedError: './temp_daily_maps/mean/2024_02_20_mean.tif' not recognized as a supported file format.

During handling of the above exception, another exception occurred:

Traceback (most recent call last):
  File "/var/www/html/Python/temp_daily.py", line 60, in <module>
    with rasterio.open(f'./temp_daily_maps/{n}/{yest_year}_{yest_mon:02d}_{yest_day:02d}_{n}.tif') as src:
  File "/home/cherryle/.local/lib/python3.10/site-packages/rasterio/env.py", line 451, in wrapper
    return f(*args, **kwds)
  File "/home/cherryle/.local/lib/python3.10/site-packages/rasterio/__init__.py", line 304, in open
    dataset = DatasetReader(path, driver=driver, sharing=sharing, **kwargs)
  File "rasterio/_base.pyx", line 312, in rasterio._base.DatasetBase.__init__
rasterio.errors.RasterioIOError: './temp_daily_maps/mean/2024_02_20_mean.tif' not recognized as a supported file format.
Traceback (most recent call last):
  File "rasterio/_base.pyx", line 310, in rasterio._base.DatasetBase.__init__
  File "rasterio/_base.pyx", line 221, in rasterio._base.open_dataset
  File "rasterio/_err.pyx", line 221, in rasterio._err.exc_wrap_pointer
rasterio._err.CPLE_OpenFailedError: './temp_daily_maps/mean/2024_02_26_mean.tif' not recognized as a supported file format.

During handling of the above exception, another exception occurred:

Traceback (most recent call last):
  File "/var/www/html/Python/temp_daily.py", line 60, in <module>
    with rasterio.open(f'./temp_daily_maps/{n}/{yest_year}_{yest_mon:02d}_{yest_day:02d}_{n}.tif') as src:
  File "/home/cherryle/.local/lib/python3.10/site-packages/rasterio/env.py", line 451, in wrapper
    return f(*args, **kwds)
  File "/home/cherryle/.local/lib/python3.10/site-packages/rasterio/__init__.py", line 304, in open
    dataset = DatasetReader(path, driver=driver, sharing=sharing, **kwargs)
  File "rasterio/_base.pyx", line 312, in rasterio._base.DatasetBase.__init__
rasterio.errors.RasterioIOError: './temp_daily_maps/mean/2024_02_26_mean.tif' not recognized as a supported file format.
Traceback (most recent call last):
  File "rasterio/_base.pyx", line 310, in rasterio._base.DatasetBase.__init__
  File "rasterio/_base.pyx", line 221, in rasterio._base.open_dataset
  File "rasterio/_err.pyx", line 221, in rasterio._err.exc_wrap_pointer
rasterio._err.CPLE_OpenFailedError: './temp_daily_maps/mean/2024_02_27_mean.tif' not recognized as a supported file format.

During handling of the above exception, another exception occurred:

Traceback (most recent call last):
  File "/var/www/html/Python/temp_daily.py", line 60, in <module>
    with rasterio.open(f'./temp_daily_maps/{n}/{yest_year}_{yest_mon:02d}_{yest_day:02d}_{n}.tif') as src:
  File "/home/cherryle/.local/lib/python3.10/site-packages/rasterio/env.py", line 451, in wrapper
    return f(*args, **kwds)
  File "/home/cherryle/.local/lib/python3.10/site-packages/rasterio/__init__.py", line 304, in open
    dataset = DatasetReader(path, driver=driver, sharing=sharing, **kwargs)
  File "rasterio/_base.pyx", line 312, in rasterio._base.DatasetBase.__init__
rasterio.errors.RasterioIOError: './temp_daily_maps/mean/2024_02_27_mean.tif' not recognized as a supported file format.
Traceback (most recent call last):
  File "rasterio/_base.pyx", line 310, in rasterio._base.DatasetBase.__init__
  File "rasterio/_base.pyx", line 221, in rasterio._base.open_dataset
  File "rasterio/_err.pyx", line 221, in rasterio._err.exc_wrap_pointer
rasterio._err.CPLE_OpenFailedError: './temp_daily_maps/mean/2024_03_09_mean.tif' not recognized as a supported file format.

During handling of the above exception, another exception occurred:

Traceback (most recent call last):
  File "/var/www/html/Python/temp_daily.py", line 60, in <module>
    with rasterio.open(f'./temp_daily_maps/{n}/{yest_year}_{yest_mon:02d}_{yest_day:02d}_{n}.tif') as src:
  File "/home/cherryle/.local/lib/python3.10/site-packages/rasterio/env.py", line 451, in wrapper
    return f(*args, **kwds)
  File "/home/cherryle/.local/lib/python3.10/site-packages/rasterio/__init__.py", line 304, in open
    dataset = DatasetReader(path, driver=driver, sharing=sharing, **kwargs)
  File "rasterio/_base.pyx", line 312, in rasterio._base.DatasetBase.__init__
rasterio.errors.RasterioIOError: './temp_daily_maps/mean/2024_03_09_mean.tif' not recognized as a supported file format.
Traceback (most recent call last):
  File "rasterio/_base.pyx", line 310, in rasterio._base.DatasetBase.__init__
  File "rasterio/_base.pyx", line 221, in rasterio._base.open_dataset
  File "rasterio/_err.pyx", line 221, in rasterio._err.exc_wrap_pointer
rasterio._err.CPLE_OpenFailedError: './temp_daily_maps/mean/2024_03_14_mean.tif' not recognized as a supported file format.

During handling of the above exception, another exception occurred:

Traceback (most recent call last):
  File "/var/www/html/Python/temp_daily.py", line 60, in <module>
    with rasterio.open(f'./temp_daily_maps/{n}/{yest_year}_{yest_mon:02d}_{yest_day:02d}_{n}.tif') as src:
  File "/home/cherryle/.local/lib/python3.10/site-packages/rasterio/env.py", line 451, in wrapper
    return f(*args, **kwds)
  File "/home/cherryle/.local/lib/python3.10/site-packages/rasterio/__init__.py", line 304, in open
    dataset = DatasetReader(path, driver=driver, sharing=sharing, **kwargs)
  File "rasterio/_base.pyx", line 312, in rasterio._base.DatasetBase.__init__
rasterio.errors.RasterioIOError: './temp_daily_maps/mean/2024_03_14_mean.tif' not recognized as a supported file format.
Traceback (most recent call last):
  File "/usr/lib/python3/dist-packages/urllib3/connectionpool.py", line 700, in urlopen
    httplib_response = self._make_request(
  File "/usr/lib/python3/dist-packages/urllib3/connectionpool.py", line 446, in _make_request
    six.raise_from(e, None)
  File "<string>", line 3, in raise_from
  File "/usr/lib/python3/dist-packages/urllib3/connectionpool.py", line 441, in _make_request
    httplib_response = conn.getresponse()
  File "/usr/lib/python3.10/http/client.py", line 1375, in getresponse
    response.begin()
  File "/usr/lib/python3.10/http/client.py", line 318, in begin
    version, status, reason = self._read_status()
  File "/usr/lib/python3.10/http/client.py", line 287, in _read_status
    raise RemoteDisconnected("Remote end closed connection without"
http.client.RemoteDisconnected: Remote end closed connection without response

During handling of the above exception, another exception occurred:

Traceback (most recent call last):
  File "/usr/lib/python3/dist-packages/requests/adapters.py", line 439, in send
    resp = conn.urlopen(
  File "/usr/lib/python3/dist-packages/urllib3/connectionpool.py", line 756, in urlopen
    retries = retries.increment(
  File "/usr/lib/python3/dist-packages/urllib3/util/retry.py", line 532, in increment
    raise six.reraise(type(error), error, _stacktrace)
  File "/usr/lib/python3/dist-packages/six.py", line 718, in reraise
    raise value.with_traceback(tb)
  File "/usr/lib/python3/dist-packages/urllib3/connectionpool.py", line 700, in urlopen
    httplib_response = self._make_request(
  File "/usr/lib/python3/dist-packages/urllib3/connectionpool.py", line 446, in _make_request
    six.raise_from(e, None)
  File "<string>", line 3, in raise_from
  File "/usr/lib/python3/dist-packages/urllib3/connectionpool.py", line 441, in _make_request
    httplib_response = conn.getresponse()
  File "/usr/lib/python3.10/http/client.py", line 1375, in getresponse
    response.begin()
  File "/usr/lib/python3.10/http/client.py", line 318, in begin
    version, status, reason = self._read_status()
  File "/usr/lib/python3.10/http/client.py", line 287, in _read_status
    raise RemoteDisconnected("Remote end closed connection without"
urllib3.exceptions.ProtocolError: ('Connection aborted.', RemoteDisconnected('Remote end closed connection without response'))

During handling of the above exception, another exception occurred:

Traceback (most recent call last):
  File "/var/www/html/Python/temp_daily.py", line 28, in <module>
    r = requests.get(mean_url)
  File "/usr/lib/python3/dist-packages/requests/api.py", line 76, in get
    return request('get', url, params=params, **kwargs)
  File "/usr/lib/python3/dist-packages/requests/api.py", line 61, in request
    return session.request(method=method, url=url, **kwargs)
  File "/usr/lib/python3/dist-packages/requests/sessions.py", line 544, in request
    resp = self.send(prep, **send_kwargs)
  File "/usr/lib/python3/dist-packages/requests/sessions.py", line 657, in send
    r = adapter.send(request, **kwargs)
  File "/usr/lib/python3/dist-packages/requests/adapters.py", line 498, in send
    raise ConnectionError(err, request=request)
requests.exceptions.ConnectionError: ('Connection aborted.', RemoteDisconnected('Remote end closed connection without response'))
Traceback (most recent call last):
  File "rasterio/_base.pyx", line 310, in rasterio._base.DatasetBase.__init__
  File "rasterio/_base.pyx", line 221, in rasterio._base.open_dataset
  File "rasterio/_err.pyx", line 221, in rasterio._err.exc_wrap_pointer
rasterio._err.CPLE_OpenFailedError: './temp_daily_maps/mean/2024_03_21_mean.tif' not recognized as a supported file format.

During handling of the above exception, another exception occurred:

Traceback (most recent call last):
  File "/var/www/html/Python/temp_daily.py", line 60, in <module>
    with rasterio.open(f'./temp_daily_maps/{n}/{yest_year}_{yest_mon:02d}_{yest_day:02d}_{n}.tif') as src:
  File "/home/cherryle/.local/lib/python3.10/site-packages/rasterio/env.py", line 451, in wrapper
    return f(*args, **kwds)
  File "/home/cherryle/.local/lib/python3.10/site-packages/rasterio/__init__.py", line 304, in open
    dataset = DatasetReader(path, driver=driver, sharing=sharing, **kwargs)
  File "rasterio/_base.pyx", line 312, in rasterio._base.DatasetBase.__init__
rasterio.errors.RasterioIOError: './temp_daily_maps/mean/2024_03_21_mean.tif' not recognized as a supported file format.
Traceback (most recent call last):
  File "/usr/lib/python3/dist-packages/urllib3/connectionpool.py", line 700, in urlopen
    httplib_response = self._make_request(
  File "/usr/lib/python3/dist-packages/urllib3/connectionpool.py", line 446, in _make_request
    six.raise_from(e, None)
  File "<string>", line 3, in raise_from
  File "/usr/lib/python3/dist-packages/urllib3/connectionpool.py", line 441, in _make_request
    httplib_response = conn.getresponse()
  File "/usr/lib/python3.10/http/client.py", line 1375, in getresponse
    response.begin()
  File "/usr/lib/python3.10/http/client.py", line 318, in begin
    version, status, reason = self._read_status()
  File "/usr/lib/python3.10/http/client.py", line 287, in _read_status
    raise RemoteDisconnected("Remote end closed connection without"
http.client.RemoteDisconnected: Remote end closed connection without response

During handling of the above exception, another exception occurred:

Traceback (most recent call last):
  File "/usr/lib/python3/dist-packages/requests/adapters.py", line 439, in send
    resp = conn.urlopen(
  File "/usr/lib/python3/dist-packages/urllib3/connectionpool.py", line 756, in urlopen
    retries = retries.increment(
  File "/usr/lib/python3/dist-packages/urllib3/util/retry.py", line 532, in increment
    raise six.reraise(type(error), error, _stacktrace)
  File "/usr/lib/python3/dist-packages/six.py", line 718, in reraise
    raise value.with_traceback(tb)
  File "/usr/lib/python3/dist-packages/urllib3/connectionpool.py", line 700, in urlopen
    httplib_response = self._make_request(
  File "/usr/lib/python3/dist-packages/urllib3/connectionpool.py", line 446, in _make_request
    six.raise_from(e, None)
  File "<string>", line 3, in raise_from
  File "/usr/lib/python3/dist-packages/urllib3/connectionpool.py", line 441, in _make_request
    httplib_response = conn.getresponse()
  File "/usr/lib/python3.10/http/client.py", line 1375, in getresponse
    response.begin()
  File "/usr/lib/python3.10/http/client.py", line 318, in begin
    version, status, reason = self._read_status()
  File "/usr/lib/python3.10/http/client.py", line 287, in _read_status
    raise RemoteDisconnected("Remote end closed connection without"
urllib3.exceptions.ProtocolError: ('Connection aborted.', RemoteDisconnected('Remote end closed connection without response'))

During handling of the above exception, another exception occurred:

Traceback (most recent call last):
  File "/var/www/html/Python/temp_daily.py", line 28, in <module>
    r = requests.get(mean_url)
  File "/usr/lib/python3/dist-packages/requests/api.py", line 76, in get
    return request('get', url, params=params, **kwargs)
  File "/usr/lib/python3/dist-packages/requests/api.py", line 61, in request
    return session.request(method=method, url=url, **kwargs)
  File "/usr/lib/python3/dist-packages/requests/sessions.py", line 544, in request
    resp = self.send(prep, **send_kwargs)
  File "/usr/lib/python3/dist-packages/requests/sessions.py", line 657, in send
    r = adapter.send(request, **kwargs)
  File "/usr/lib/python3/dist-packages/requests/adapters.py", line 498, in send
    raise ConnectionError(err, request=request)
requests.exceptions.ConnectionError: ('Connection aborted.', RemoteDisconnected('Remote end closed connection without response'))
Traceback (most recent call last):
  File "/usr/lib/python3/dist-packages/urllib3/connectionpool.py", line 700, in urlopen
    httplib_response = self._make_request(
  File "/usr/lib/python3/dist-packages/urllib3/connectionpool.py", line 446, in _make_request
    six.raise_from(e, None)
  File "<string>", line 3, in raise_from
  File "/usr/lib/python3/dist-packages/urllib3/connectionpool.py", line 441, in _make_request
    httplib_response = conn.getresponse()
  File "/usr/lib/python3.10/http/client.py", line 1375, in getresponse
    response.begin()
  File "/usr/lib/python3.10/http/client.py", line 318, in begin
    version, status, reason = self._read_status()
  File "/usr/lib/python3.10/http/client.py", line 287, in _read_status
    raise RemoteDisconnected("Remote end closed connection without"
http.client.RemoteDisconnected: Remote end closed connection without response

During handling of the above exception, another exception occurred:

Traceback (most recent call last):
  File "/usr/lib/python3/dist-packages/requests/adapters.py", line 439, in send
    resp = conn.urlopen(
  File "/usr/lib/python3/dist-packages/urllib3/connectionpool.py", line 756, in urlopen
    retries = retries.increment(
  File "/usr/lib/python3/dist-packages/urllib3/util/retry.py", line 532, in increment
    raise six.reraise(type(error), error, _stacktrace)
  File "/usr/lib/python3/dist-packages/six.py", line 718, in reraise
    raise value.with_traceback(tb)
  File "/usr/lib/python3/dist-packages/urllib3/connectionpool.py", line 700, in urlopen
    httplib_response = self._make_request(
  File "/usr/lib/python3/dist-packages/urllib3/connectionpool.py", line 446, in _make_request
    six.raise_from(e, None)
  File "<string>", line 3, in raise_from
  File "/usr/lib/python3/dist-packages/urllib3/connectionpool.py", line 441, in _make_request
    httplib_response = conn.getresponse()
  File "/usr/lib/python3.10/http/client.py", line 1375, in getresponse
    response.begin()
  File "/usr/lib/python3.10/http/client.py", line 318, in begin
    version, status, reason = self._read_status()
  File "/usr/lib/python3.10/http/client.py", line 287, in _read_status
    raise RemoteDisconnected("Remote end closed connection without"
urllib3.exceptions.ProtocolError: ('Connection aborted.', RemoteDisconnected('Remote end closed connection without response'))

During handling of the above exception, another exception occurred:

Traceback (most recent call last):
  File "/var/www/html/Python/temp_daily.py", line 28, in <module>
    r = requests.get(mean_url)
  File "/usr/lib/python3/dist-packages/requests/api.py", line 76, in get
    return request('get', url, params=params, **kwargs)
  File "/usr/lib/python3/dist-packages/requests/api.py", line 61, in request
    return session.request(method=method, url=url, **kwargs)
  File "/usr/lib/python3/dist-packages/requests/sessions.py", line 544, in request
    resp = self.send(prep, **send_kwargs)
  File "/usr/lib/python3/dist-packages/requests/sessions.py", line 657, in send
    r = adapter.send(request, **kwargs)
  File "/usr/lib/python3/dist-packages/requests/adapters.py", line 498, in send
    raise ConnectionError(err, request=request)
requests.exceptions.ConnectionError: ('Connection aborted.', RemoteDisconnected('Remote end closed connection without response'))
