Traceback (most recent call last):
  File "rasterio/_base.pyx", line 310, in rasterio._base.DatasetBase.__init__
  File "rasterio/_base.pyx", line 221, in rasterio._base.open_dataset
  File "rasterio/_err.pyx", line 221, in rasterio._err.exc_wrap_pointer
rasterio._err.CPLE_OpenFailedError: './temp_daily_maps/mean/2025_10_02_mean.tif' not recognized as a supported file format.

During handling of the above exception, another exception occurred:

Traceback (most recent call last):
  File "/var/www/html/Python/temp_daily.py", line 60, in <module>
    with rasterio.open(f'./temp_daily_maps/{n}/{yest_year}_{yest_mon:02d}_{yest_day:02d}_{n}.tif') as src:
         ^^^^^^^^^^^^^^^^^^^^^^^^^^^^^^^^^^^^^^^^^^^^^^^^^^^^^^^^^^^^^^^^^^^^^^^^^^^^^^^^^^^^^^^^^
  File "/usr/lib/python3/dist-packages/rasterio/env.py", line 451, in wrapper
    return f(*args, **kwds)
           ^^^^^^^^^^^^^^^^
  File "/usr/lib/python3/dist-packages/rasterio/__init__.py", line 304, in open
    dataset = DatasetReader(path, driver=driver, sharing=sharing, **kwargs)
              ^^^^^^^^^^^^^^^^^^^^^^^^^^^^^^^^^^^^^^^^^^^^^^^^^^^^^^^^^^^^^
  File "rasterio/_base.pyx", line 312, in rasterio._base.DatasetBase.__init__
rasterio.errors.RasterioIOError: './temp_daily_maps/mean/2025_10_02_mean.tif' not recognized as a supported file format.
